2025-07-28 11:50:32,939 - __main__ - ERROR - main:478 - Input path does not exist: /nonexistent/file.pdf
2025-07-28 11:54:30,839 - error_handler - ERROR - wrapper:502 - Error in PDF document parsing: PDF file is empty: empty.pdf
2025-07-28 11:54:30,840 - error_handler - ERROR - _log_detailed_error:368 - Detailed error information: {'context': 'PDF document parsing', 'error_type': 'PDFProcessingError', 'error_message': 'PDF file is empty: empty.pdf', 'traceback': 'Traceback (most recent call last):\n  File "/home/himanshu/adobe-hack/Challenge_1a/error_handler.py", line 498, in wrapper\n    result = func(*args, **kwargs)\n             ^^^^^^^^^^^^^^^^^^^^^\n  File "/home/himanshu/adobe-hack/Challenge_1a/pdf_parser.py", line 68, in parse_document\n    raise PDFProcessingError(\nerror_handler.PDFProcessingError: PDF file is empty: empty.pdf\n', 'additional_info': {}}
2025-07-28 12:11:59,705 - error_handler - ERROR - wrapper:502 - Error in PDF document parsing: Cannot open PDF file: /tmp/tmpmb674jpz/test.pdf. Error: Failed to open file '/tmp/tmpmb674jpz/test.pdf'.
2025-07-28 12:11:59,712 - error_handler - ERROR - _log_detailed_error:368 - Detailed error information: {'context': 'PDF document parsing', 'error_type': 'PDFProcessingError', 'error_message': "Cannot open PDF file: /tmp/tmpmb674jpz/test.pdf. Error: Failed to open file '/tmp/tmpmb674jpz/test.pdf'.", 'traceback': 'Traceback (most recent call last):\n  File "/home/himanshu/adobe-hack/Challenge_1a/.venv/lib/python3.12/site-packages/pymupdf/__init__.py", line 2974, in __init__\n    doc = mupdf.fz_open_document(filename)\n          ^^^^^^^^^^^^^^^^^^^^^^^^^^^^^^^^\n  File "/home/himanshu/adobe-hack/Challenge_1a/.venv/lib/python3.12/site-packages/pymupdf/mupdf.py", line 48440, in fz_open_document\n    return _mupdf.fz_open_document(filename)\n           ^^^^^^^^^^^^^^^^^^^^^^^^^^^^^^^^^\npymupdf.mupdf.FzErrorFormat: code=7: no objects found\n\nThe above exception was the direct cause of the following exception:\n\nTraceback (most recent call last):\n  File "/home/himanshu/adobe-hack/Challenge_1a/pdf_parser.py", line 77, in parse_document\n    self.document = fitz.open(pdf_path)\n                    ^^^^^^^^^^^^^^^^^^^\n  File "/home/himanshu/adobe-hack/Challenge_1a/.venv/lib/python3.12/site-packages/pymupdf/__init__.py", line 2977, in __init__\n    raise FileDataError(f\'Failed to open file {filename!r}.\') from e\npymupdf.FileDataError: Failed to open file \'/tmp/tmpmb674jpz/test.pdf\'.\n\nDuring handling of the above exception, another exception occurred:\n\nTraceback (most recent call last):\n  File "/home/himanshu/adobe-hack/Challenge_1a/error_handler.py", line 498, in wrapper\n    result = func(*args, **kwargs)\n             ^^^^^^^^^^^^^^^^^^^^^\n  File "/home/himanshu/adobe-hack/Challenge_1a/pdf_parser.py", line 92, in parse_document\n    raise PDFProcessingError(\nerror_handler.PDFProcessingError: Cannot open PDF file: /tmp/tmpmb674jpz/test.pdf. Error: Failed to open file \'/tmp/tmpmb674jpz/test.pdf\'.\n', 'additional_info': {}}
2025-07-28 12:12:01,289 - error_handler - ERROR - wrapper:502 - Error in PDF document parsing: PDF file is corrupted: /tmp/tmp0v9iqz3w/corrupted.pdf
2025-07-28 12:12:01,290 - error_handler - ERROR - _log_detailed_error:368 - Detailed error information: {'context': 'PDF document parsing', 'error_type': 'PDFProcessingError', 'error_message': 'PDF file is corrupted: /tmp/tmp0v9iqz3w/corrupted.pdf', 'traceback': 'Traceback (most recent call last):\n  File "/home/himanshu/adobe-hack/Challenge_1a/.venv/lib/python3.12/site-packages/pymupdf/__init__.py", line 2974, in __init__\n    doc = mupdf.fz_open_document(filename)\n          ^^^^^^^^^^^^^^^^^^^^^^^^^^^^^^^^\n  File "/home/himanshu/adobe-hack/Challenge_1a/.venv/lib/python3.12/site-packages/pymupdf/mupdf.py", line 48440, in fz_open_document\n    return _mupdf.fz_open_document(filename)\n           ^^^^^^^^^^^^^^^^^^^^^^^^^^^^^^^^^\npymupdf.mupdf.FzErrorFormat: code=7: no objects found\n\nThe above exception was the direct cause of the following exception:\n\nTraceback (most recent call last):\n  File "/home/himanshu/adobe-hack/Challenge_1a/pdf_parser.py", line 77, in parse_document\n    self.document = fitz.open(pdf_path)\n                    ^^^^^^^^^^^^^^^^^^^\n  File "/home/himanshu/adobe-hack/Challenge_1a/.venv/lib/python3.12/site-packages/pymupdf/__init__.py", line 2977, in __init__\n    raise FileDataError(f\'Failed to open file {filename!r}.\') from e\npymupdf.FileDataError: Failed to open file \'/tmp/tmp0v9iqz3w/corrupted.pdf\'.\n\nDuring handling of the above exception, another exception occurred:\n\nTraceback (most recent call last):\n  File "/home/himanshu/adobe-hack/Challenge_1a/error_handler.py", line 498, in wrapper\n    result = func(*args, **kwargs)\n             ^^^^^^^^^^^^^^^^^^^^^\n  File "/home/himanshu/adobe-hack/Challenge_1a/pdf_parser.py", line 86, in parse_document\n    raise PDFProcessingError(\nerror_handler.PDFProcessingError: PDF file is corrupted: /tmp/tmp0v9iqz3w/corrupted.pdf\n', 'additional_info': {}}
2025-07-28 12:12:01,927 - error_handler - ERROR - wrapper:502 - Error in PDF document parsing: PDF file is empty: /tmp/tmpde44zs62/empty.pdf
2025-07-28 12:12:01,927 - error_handler - ERROR - _log_detailed_error:368 - Detailed error information: {'context': 'PDF document parsing', 'error_type': 'PDFProcessingError', 'error_message': 'PDF file is empty: /tmp/tmpde44zs62/empty.pdf', 'traceback': 'Traceback (most recent call last):\n  File "/home/himanshu/adobe-hack/Challenge_1a/error_handler.py", line 498, in wrapper\n    result = func(*args, **kwargs)\n             ^^^^^^^^^^^^^^^^^^^^^\n  File "/home/himanshu/adobe-hack/Challenge_1a/pdf_parser.py", line 68, in parse_document\n    raise PDFProcessingError(\nerror_handler.PDFProcessingError: PDF file is empty: /tmp/tmpde44zs62/empty.pdf\n', 'additional_info': {}}
2025-07-28 12:12:01,966 - main - ERROR - process_pdf:359 - Error processing PDF input/E0CCG5S239.pdf: Model loading failed
2025-07-28 12:21:04,601 - __main__ - ERROR - main:478 - Input path does not exist: input/document.pdf
